Workbook

Sheet aoc
A1: . | B1: . | C1: . | D1: . | E1: . | F1: . | G1: . | H1: S | I1: . | J1: . | K1: . | L1: . | M1: . | N1: . | O1: .
A2: . | B2: . | C2: . | D2: . | E2: . | F2: . | G2: . | H2: 1 | I2: . | J2: . | K2: . | L2: . | M2: . | N2: . | O2: .
A3: . | B3: . | C3: . | D3: . | E3: . | F3: . | G3: 1 | H3: ^ | I3: 1 | J3: . | K3: . | L3: . | M3: . | N3: . | O3: .
A4: . | B4: . | C4: . | D4: . | E4: . | F4: . | G4: 1 | H4: . | I4: 1 | J4: . | K4: . | L4: . | M4: . | N4: . | O4: .
A5: . | B5: . | C5: . | D5: . | E5: . | F5: 1 | G5: ^ | H5: 2 | I5: ^ | J5: 1 | K5: . | L5: . | M5: . | N5: . | O5: .
A6: . | B6: . | C6: . | D6: . | E6: . | F6: 1 | G6: . | H6: 2 | I6: . | J6: 1 | K6: . | L6: . | M6: . | N6: . | O6: .
A7: . | B7: . | C7: . | D7: . | E7: 1 | F7: ^ | G7: 3 | H7: ^ | I7: 3 | J7: ^ | K7: 1 | L7: . | M7: . | N7: . | O7: .
A8: . | B8: . | C8: . | D8: . | E8: 1 | F8: . | G8: 3 | H8: . | I8: 3 | J8: . | K8: 1 | L8: . | M8: . | N8: . | O8: .
A9: . | B9: . | C9: . | D9: 1 | E9: ^ | F9: 4 | G9: ^ | H9: 3 | I9: 3 | J9: 1 | K9: ^ | L9: 1 | M9: . | N9: . | O9: .
A10: . | B10: . | C10: . | D10: 1 | E10: . | F10: 4 | G10: . | H10: 3 | I10: 3 | J10: 1 | K10: . | L10: 1 | M10: . | N10: . | O10: .
A11: . | B11: . | C11: 1 | D11: ^ | E11: 5 | F11: ^ | G11: 4 | H11: 3 | I11: 4 | J11: ^ | K11: 2 | L11: ^ | M11: 1 | N11: . | O11: .
A12: . | B12: . | C12: 1 | D12: . | E12: 5 | F12: . | G12: 4 | H12: 3 | I12: 4 | J12: . | K12: 2 | L12: . | M12: 1 | N12: . | O12: .
A13: . | B13: 1 | C13: ^ | D13: 1 | E13: 5 | F13: 4 | G13: ^ | H13: 7 | I13: 4 | J13: . | K13: 2 | L13: 1 | M13: ^ | N13: 1 | O13: .
A14: . | B14: 1 | C14: . | D14: 1 | E14: 5 | F14: 4 | G14: . | H14: 7 | I14: 4 | J14: . | K14: 2 | L14: 1 | M14: . | N14: 1 | O14: .
A15: 1 | B15: ^ | C15: 2 | D15: ^ | E15: 10 | F15: ^ | G15: 11 | H15: ^ | I15: 11 | J15: ^ | K15: 2 | L15: 1 | M15: 1 | N15: ^ | O15: 1
A16: 1 | B16: . | C16: 2 | D16: . | E16: 10 | F16: . | G16: 11 | H16: . | I16: 11 | J16: . | K16: 2 | L16: 1 | M16: 1 | N16: . | O16: 1 | R16: =sum(A16:O16) -> 40

Sheet raw_ex
A1: . | B1: . | C1: . | D1: . | E1: . | F1: . | G1: . | H1: S | I1: . | J1: . | K1: . | L1: . | M1: . | N1: . | O1: .
A2: . | B2: . | C2: . | D2: . | E2: . | F2: . | G2: . | H2: . | I2: . | J2: . | K2: . | L2: . | M2: . | N2: . | O2: .
A3: . | B3: . | C3: . | D3: . | E3: . | F3: . | G3: . | H3: ^ | I3: . | J3: . | K3: . | L3: . | M3: . | N3: . | O3: .
A4: . | B4: . | C4: . | D4: . | E4: . | F4: . | G4: . | H4: . | I4: . | J4: . | K4: . | L4: . | M4: . | N4: . | O4: .
A5: . | B5: . | C5: . | D5: . | E5: . | F5: . | G5: ^ | H5: . | I5: ^ | J5: . | K5: . | L5: . | M5: . | N5: . | O5: .
A6: . | B6: . | C6: . | D6: . | E6: . | F6: . | G6: . | H6: . | I6: . | J6: . | K6: . | L6: . | M6: . | N6: . | O6: .
A7: . | B7: . | C7: . | D7: . | E7: . | F7: ^ | G7: . | H7: ^ | I7: . | J7: ^ | K7: . | L7: . | M7: . | N7: . | O7: .
A8: . | B8: . | C8: . | D8: . | E8: . | F8: . | G8: . | H8: . | I8: . | J8: . | K8: . | L8: . | M8: . | N8: . | O8: .
A9: . | B9: . | C9: . | D9: . | E9: ^ | F9: . | G9: ^ | H9: . | I9: . | J9: . | K9: ^ | L9: . | M9: . | N9: . | O9: .
A10: . | B10: . | C10: . | D10: . | E10: . | F10: . | G10: . | H10: . | I10: . | J10: . | K10: . | L10: . | M10: . | N10: . | O10: .
A11: . | B11: . | C11: . | D11: ^ | E11: . | F11: ^ | G11: . | H11: . | I11: . | J11: ^ | K11: . | L11: ^ | M11: . | N11: . | O11: .
A12: . | B12: . | C12: . | D12: . | E12: . | F12: . | G12: . | H12: . | I12: . | J12: . | K12: . | L12: . | M12: . | N12: . | O12: .
... A16: . | B16: . | C16: . | D16: . | E16: . | F16: . | G16: . | H16: . | I16: . | J16: . | K16: . | L16: . | M16: . | N16: . | O16: .

Sheet Example solution
B1: =if(raw_ex!A1=".","",raw_ex!A1) | C1: =if(raw_ex!B1=".","",raw_ex!B1) | D1: =if(raw_ex!C1=".","",raw_ex!C1) | E1: =if(raw_ex!D1=".","",raw_ex!D1) | F1: =if(raw_ex!E1=".","",raw_ex!E1) | G1: =if(raw_ex!F1=".","",raw_ex!F1) | H1: =if(raw_ex!G1=".","",raw_ex!G1) | I1: =if(raw_ex!H1=".","",raw_ex!H1) -> S | ... P1: =if(raw_ex!O1=".","",raw_ex!O1)
B2: =if(raw_ex!A2="^","^",if(B1="^","",if(B1="S",1,B1+if(C2="^",C1+if(A2="^",A1,0),if(A2="^",A1,0))))) -> 0 | C2: =if(raw_ex!B2="^","^",if(C1="^","",if(C1="S",1,C1+if(D2="^",D1+if(B2="^",B1,0),if(B2="^",B1,0))))) -> 0 | D2: =if(raw_ex!C2="^","^",if(D1="^","",if(D1="S",1,D1+if(E2="^",E1+if(C2="^",C1,0),if(C2="^",C1,0))))) -> 0 | E2: =if(raw_ex!D2="^","^",if(E1="^","",if(E1="S",1,E1+if(F2="^",F1+if(D2="^",D1,0),if(D2="^",D1,0))))) -> 0 | F2: =if(raw_ex!E2="^","^",if(F1="^","",if(F1="S",1,F1+if(G2="^",G1+if(E2="^",E1,0),if(E2="^",E1,0))))) -> 0 | G2: =if(raw_ex!F2="^","^",if(G1="^","",if(G1="S",1,G1+if(H2="^",H1+if(F2="^",F1,0),if(F2="^",F1,0))))) -> 0 | H2: =if(raw_ex!G2="^","^",if(H1="^","",if(H1="S",1,H1+if(I2="^",I1+if(G2="^",G1,0),if(G2="^",G1,0))))) -> 0 | I2: =if(raw_ex!H2="^","^",if(I1="^","",if(I1="S",1,I1+if(J2="^",J1+if(H2="^",H1,0),if(H2="^",H1,0))))) -> 1 | ... P2: =if(raw_ex!O2="^","^",if(P1="^","",if(P1="S",1,P1+if(Q2="^",Q1+if(O2="^",O1,0),if(O2="^",O1,0))))) -> 0
B3: =if(raw_ex!A3="^","^",if(B2="^","",if(B2="S",1,B2+if(C3="^",C2+if(A3="^",A2,0),if(A3="^",A2,0))))) -> 0 | C3: =if(raw_ex!B3="^","^",if(C2="^","",if(C2="S",1,C2+if(D3="^",D2+if(B3="^",B2,0),if(B3="^",B2,0))))) -> 0 | D3: =if(raw_ex!C3="^","^",if(D2="^","",if(D2="S",1,D2+if(E3="^",E2+if(C3="^",C2,0),if(C3="^",C2,0))))) -> 0 | E3: =if(raw_ex!D3="^","^",if(E2="^","",if(E2="S",1,E2+if(F3="^",F2+if(D3="^",D2,0),if(D3="^",D2,0))))) -> 0 | F3: =if(raw_ex!E3="^","^",if(F2="^","",if(F2="S",1,F2+if(G3="^",G2+if(E3="^",E2,0),if(E3="^",E2,0))))) -> 0 | G3: =if(raw_ex!F3="^","^",if(G2="^","",if(G2="S",1,G2+if(H3="^",H2+if(F3="^",F2,0),if(F3="^",F2,0))))) -> 0 | H3: =if(raw_ex!G3="^","^",if(H2="^","",if(H2="S",1,H2+if(I3="^",I2+if(G3="^",G2,0),if(G3="^",G2,0))))) -> 1 | I3: =if(raw_ex!H3="^","^",if(I2="^","",if(I2="S",1,I2+if(J3="^",J2+if(H3="^",H2,0),if(H3="^",H2,0))))) -> ^ | ... P3: =if(raw_ex!O3="^","^",if(P2="^","",if(P2="S",1,P2+if(Q3="^",Q2+if(O3="^",O2,0),if(O3="^",O2,0))))) -> 0
B4: =if(raw_ex!A4="^","^",if(B3="^","",if(B3="S",1,B3+if(C4="^",C3+if(A4="^",A3,0),if(A4="^",A3,0))))) -> 0 | C4: =if(raw_ex!B4="^","^",if(C3="^","",if(C3="S",1,C3+if(D4="^",D3+if(B4="^",B3,0),if(B4="^",B3,0))))) -> 0 | D4: =if(raw_ex!C4="^","^",if(D3="^","",if(D3="S",1,D3+if(E4="^",E3+if(C4="^",C3,0),if(C4="^",C3,0))))) -> 0 | E4: =if(raw_ex!D4="^","^",if(E3="^","",if(E3="S",1,E3+if(F4="^",F3+if(D4="^",D3,0),if(D4="^",D3,0))))) -> 0 | F4: =if(raw_ex!E4="^","^",if(F3="^","",if(F3="S",1,F3+if(G4="^",G3+if(E4="^",E3,0),if(E4="^",E3,0))))) -> 0 | G4: =if(raw_ex!F4="^","^",if(G3="^","",if(G3="S",1,G3+if(H4="^",H3+if(F4="^",F3,0),if(F4="^",F3,0))))) -> 0 | H4: =if(raw_ex!G4="^","^",if(H3="^","",if(H3="S",1,H3+if(I4="^",I3+if(G4="^",G3,0),if(G4="^",G3,0))))) -> 1 | I4: =if(raw_ex!H4="^","^",if(I3="^","",if(I3="S",1,I3+if(J4="^",J3+if(H4="^",H3,0),if(H4="^",H3,0))))) | ... P4: =if(raw_ex!O4="^","^",if(P3="^","",if(P3="S",1,P3+if(Q4="^",Q3+if(O4="^",O3,0),if(O4="^",O3,0))))) -> 0
B5: =if(raw_ex!A5="^","^",if(B4="^","",if(B4="S",1,B4+if(C5="^",C4+if(A5="^",A4,0),if(A5="^",A4,0))))) -> 0 | C5: =if(raw_ex!B5="^","^",if(C4="^","",if(C4="S",1,C4+if(D5="^",D4+if(B5="^",B4,0),if(B5="^",B4,0))))) -> 0 | D5: =if(raw_ex!C5="^","^",if(D4="^","",if(D4="S",1,D4+if(E5="^",E4+if(C5="^",C4,0),if(C5="^",C4,0))))) -> 0 | E5: =if(raw_ex!D5="^","^",if(E4="^","",if(E4="S",1,E4+if(F5="^",F4+if(D5="^",D4,0),if(D5="^",D4,0))))) -> 0 | F5: =if(raw_ex!E5="^","^",if(F4="^","",if(F4="S",1,F4+if(G5="^",G4+if(E5="^",E4,0),if(E5="^",E4,0))))) -> 0 | G5: =if(raw_ex!F5="^","^",if(G4="^","",if(G4="S",1,G4+if(H5="^",H4+if(F5="^",F4,0),if(F5="^",F4,0))))) -> 1 | H5: =if(raw_ex!G5="^","^",if(H4="^","",if(H4="S",1,H4+if(I5="^",I4+if(G5="^",G4,0),if(G5="^",G4,0))))) -> ^ | I5: =if(raw_ex!H5="^","^",if(I4="^","",if(I4="S",1,I4+if(J5="^",J4+if(H5="^",H4,0),if(H5="^",H4,0))))) -> 2 | ... P5: =if(raw_ex!O5="^","^",if(P4="^","",if(P4="S",1,P4+if(Q5="^",Q4+if(O5="^",O4,0),if(O5="^",O4,0))))) -> 0
B6: =if(raw_ex!A6="^","^",if(B5="^","",if(B5="S",1,B5+if(C6="^",C5+if(A6="^",A5,0),if(A6="^",A5,0))))) -> 0 | C6: =if(raw_ex!B6="^","^",if(C5="^","",if(C5="S",1,C5+if(D6="^",D5+if(B6="^",B5,0),if(B6="^",B5,0))))) -> 0 | D6: =if(raw_ex!C6="^","^",if(D5="^","",if(D5="S",1,D5+if(E6="^",E5+if(C6="^",C5,0),if(C6="^",C5,0))))) -> 0 | E6: =if(raw_ex!D6="^","^",if(E5="^","",if(E5="S",1,E5+if(F6="^",F5+if(D6="^",D5,0),if(D6="^",D5,0))))) -> 0 | F6: =if(raw_ex!E6="^","^",if(F5="^","",if(F5="S",1,F5+if(G6="^",G5+if(E6="^",E5,0),if(E6="^",E5,0))))) -> 0 | G6: =if(raw_ex!F6="^","^",if(G5="^","",if(G5="S",1,G5+if(H6="^",H5+if(F6="^",F5,0),if(F6="^",F5,0))))) -> 1 | H6: =if(raw_ex!G6="^","^",if(H5="^","",if(H5="S",1,H5+if(I6="^",I5+if(G6="^",G5,0),if(G6="^",G5,0))))) | I6: =if(raw_ex!H6="^","^",if(I5="^","",if(I5="S",1,I5+if(J6="^",J5+if(H6="^",H5,0),if(H6="^",H5,0))))) -> 2 | ... P6: =if(raw_ex!O6="^","^",if(P5="^","",if(P5="S",1,P5+if(Q6="^",Q5+if(O6="^",O5,0),if(O6="^",O5,0))))) -> 0
B7: =if(raw_ex!A7="^","^",if(B6="^","",if(B6="S",1,B6+if(C7="^",C6+if(A7="^",A6,0),if(A7="^",A6,0))))) -> 0 | C7: =if(raw_ex!B7="^","^",if(C6="^","",if(C6="S",1,C6+if(D7="^",D6+if(B7="^",B6,0),if(B7="^",B6,0))))) -> 0 | D7: =if(raw_ex!C7="^","^",if(D6="^","",if(D6="S",1,D6+if(E7="^",E6+if(C7="^",C6,0),if(C7="^",C6,0))))) -> 0 | E7: =if(raw_ex!D7="^","^",if(E6="^","",if(E6="S",1,E6+if(F7="^",F6+if(D7="^",D6,0),if(D7="^",D6,0))))) -> 0 | F7: =if(raw_ex!E7="^","^",if(F6="^","",if(F6="S",1,F6+if(G7="^",G6+if(E7="^",E6,0),if(E7="^",E6,0))))) -> 1 | G7: =if(raw_ex!F7="^","^",if(G6="^","",if(G6="S",1,G6+if(H7="^",H6+if(F7="^",F6,0),if(F7="^",F6,0))))) -> ^ | H7: =if(raw_ex!G7="^","^",if(H6="^","",if(H6="S",1,H6+if(I7="^",I6+if(G7="^",G6,0),if(G7="^",G6,0))))) -> 3 | I7: =if(raw_ex!H7="^","^",if(I6="^","",if(I6="S",1,I6+if(J7="^",J6+if(H7="^",H6,0),if(H7="^",H6,0))))) -> ^ | ... P7: =if(raw_ex!O7="^","^",if(P6="^","",if(P6="S",1,P6+if(Q7="^",Q6+if(O7="^",O6,0),if(O7="^",O6,0))))) -> 0
B8: =if(raw_ex!A8="^","^",if(B7="^","",if(B7="S",1,B7+if(C8="^",C7+if(A8="^",A7,0),if(A8="^",A7,0))))) -> 0 | C8: =if(raw_ex!B8="^","^",if(C7="^","",if(C7="S",1,C7+if(D8="^",D7+if(B8="^",B7,0),if(B8="^",B7,0))))) -> 0 | D8: =if(raw_ex!C8="^","^",if(D7="^","",if(D7="S",1,D7+if(E8="^",E7+if(C8="^",C7,0),if(C8="^",C7,0))))) -> 0 | E8: =if(raw_ex!D8="^","^",if(E7="^","",if(E7="S",1,E7+if(F8="^",F7+if(D8="^",D7,0),if(D8="^",D7,0))))) -> 0 | F8: =if(raw_ex!E8="^","^",if(F7="^","",if(F7="S",1,F7+if(G8="^",G7+if(E8="^",E7,0),if(E8="^",E7,0))))) -> 1 | G8: =if(raw_ex!F8="^","^",if(G7="^","",if(G7="S",1,G7+if(H8="^",H7+if(F8="^",F7,0),if(F8="^",F7,0))))) | H8: =if(raw_ex!G8="^","^",if(H7="^","",if(H7="S",1,H7+if(I8="^",I7+if(G8="^",G7,0),if(G8="^",G7,0))))) -> 3 | I8: =if(raw_ex!H8="^","^",if(I7="^","",if(I7="S",1,I7+if(J8="^",J7+if(H8="^",H7,0),if(H8="^",H7,0))))) | ... P8: =if(raw_ex!O8="^","^",if(P7="^","",if(P7="S",1,P7+if(Q8="^",Q7+if(O8="^",O7,0),if(O8="^",O7,0))))) -> 0
B9: =if(raw_ex!A9="^","^",if(B8="^","",if(B8="S",1,B8+if(C9="^",C8+if(A9="^",A8,0),if(A9="^",A8,0))))) -> 0 | C9: =if(raw_ex!B9="^","^",if(C8="^","",if(C8="S",1,C8+if(D9="^",D8+if(B9="^",B8,0),if(B9="^",B8,0))))) -> 0 | D9: =if(raw_ex!C9="^","^",if(D8="^","",if(D8="S",1,D8+if(E9="^",E8+if(C9="^",C8,0),if(C9="^",C8,0))))) -> 0 | E9: =if(raw_ex!D9="^","^",if(E8="^","",if(E8="S",1,E8+if(F9="^",F8+if(D9="^",D8,0),if(D9="^",D8,0))))) -> 1 | F9: =if(raw_ex!E9="^","^",if(F8="^","",if(F8="S",1,F8+if(G9="^",G8+if(E9="^",E8,0),if(E9="^",E8,0))))) -> ^ | G9: =if(raw_ex!F9="^","^",if(G8="^","",if(G8="S",1,G8+if(H9="^",H8+if(F9="^",F8,0),if(F9="^",F8,0))))) -> 4 | H9: =if(raw_ex!G9="^","^",if(H8="^","",if(H8="S",1,H8+if(I9="^",I8+if(G9="^",G8,0),if(G9="^",G8,0))))) -> ^ | I9: =if(raw_ex!H9="^","^",if(I8="^","",if(I8="S",1,I8+if(J9="^",J8+if(H9="^",H8,0),if(H9="^",H8,0))))) -> 3 | ... P9: =if(raw_ex!O9="^","^",if(P8="^","",if(P8="S",1,P8+if(Q9="^",Q8+if(O9="^",O8,0),if(O9="^",O8,0))))) -> 0
B10: =if(raw_ex!A10="^","^",if(B9="^","",if(B9="S",1,B9+if(C10="^",C9+if(A10="^",A9,0),if(A10="^",A9,0))))) -> 0 | C10: =if(raw_ex!B10="^","^",if(C9="^","",if(C9="S",1,C9+if(D10="^",D9+if(B10="^",B9,0),if(B10="^",B9,0))))) -> 0 | D10: =if(raw_ex!C10="^","^",if(D9="^","",if(D9="S",1,D9+if(E10="^",E9+if(C10="^",C9,0),if(C10="^",C9,0))))) -> 0 | E10: =if(raw_ex!D10="^","^",if(E9="^","",if(E9="S",1,E9+if(F10="^",F9+if(D10="^",D9,0),if(D10="^",D9,0))))) -> 1 | F10: =if(raw_ex!E10="^","^",if(F9="^","",if(F9="S",1,F9+if(G10="^",G9+if(E10="^",E9,0),if(E10="^",E9,0))))) | G10: =if(raw_ex!F10="^","^",if(G9="^","",if(G9="S",1,G9+if(H10="^",H9+if(F10="^",F9,0),if(F10="^",F9,0))))) -> 4 | H10: =if(raw_ex!G10="^","^",if(H9="^","",if(H9="S",1,H9+if(I10="^",I9+if(G10="^",G9,0),if(G10="^",G9,0))))) | I10: =if(raw_ex!H10="^","^",if(I9="^","",if(I9="S",1,I9+if(J10="^",J9+if(H10="^",H9,0),if(H10="^",H9,0))))) -> 3 | ... P10: =if(raw_ex!O10="^","^",if(P9="^","",if(P9="S",1,P9+if(Q10="^",Q9+if(O10="^",O9,0),if(O10="^",O9,0))))) -> 0
B11: =if(raw_ex!A11="^","^",if(B10="^","",if(B10="S",1,B10+if(C11="^",C10+if(A11="^",A10,0),if(A11="^",A10,0))))) -> 0 | C11: =if(raw_ex!B11="^","^",if(C10="^","",if(C10="S",1,C10+if(D11="^",D10+if(B11="^",B10,0),if(B11="^",B10,0))))) -> 0 | D11: =if(raw_ex!C11="^","^",if(D10="^","",if(D10="S",1,D10+if(E11="^",E10+if(C11="^",C10,0),if(C11="^",C10,0))))) -> 1 | E11: =if(raw_ex!D11="^","^",if(E10="^","",if(E10="S",1,E10+if(F11="^",F10+if(D11="^",D10,0),if(D11="^",D10,0))))) -> ^ | F11: =if(raw_ex!E11="^","^",if(F10="^","",if(F10="S",1,F10+if(G11="^",G10+if(E11="^",E10,0),if(E11="^",E10,0))))) -> 5 | G11: =if(raw_ex!F11="^","^",if(G10="^","",if(G10="S",1,G10+if(H11="^",H10+if(F11="^",F10,0),if(F11="^",F10,0))))) -> ^ | H11: =if(raw_ex!G11="^","^",if(H10="^","",if(H10="S",1,H10+if(I11="^",I10+if(G11="^",G10,0),if(G11="^",G10,0))))) -> 4 | I11: =if(raw_ex!H11="^","^",if(I10="^","",if(I10="S",1,I10+if(J11="^",J10+if(H11="^",H10,0),if(H11="^",H10,0))))) -> 3 | ... P11: =if(raw_ex!O11="^","^",if(P10="^","",if(P10="S",1,P10+if(Q11="^",Q10+if(O11="^",O10,0),if(O11="^",O10,0))))) -> 0
B12: =if(raw_ex!A12="^","^",if(B11="^","",if(B11="S",1,B11+if(C12="^",C11+if(A12="^",A11,0),if(A12="^",A11,0))))) -> 0 | C12: =if(raw_ex!B12="^","^",if(C11="^","",if(C11="S",1,C11+if(D12="^",D11+if(B12="^",B11,0),if(B12="^",B11,0))))) -> 0 | D12: =if(raw_ex!C12="^","^",if(D11="^","",if(D11="S",1,D11+if(E12="^",E11+if(C12="^",C11,0),if(C12="^",C11,0))))) -> 1 | E12: =if(raw_ex!D12="^","^",if(E11="^","",if(E11="S",1,E11+if(F12="^",F11+if(D12="^",D11,0),if(D12="^",D11,0))))) | F12: =if(raw_ex!E12="^","^",if(F11="^","",if(F11="S",1,F11+if(G12="^",G11+if(E12="^",E11,0),if(E12="^",E11,0))))) -> 5 | G12: =if(raw_ex!F12="^","^",if(G11="^","",if(G11="S",1,G11+if(H12="^",H11+if(F12="^",F11,0),if(F12="^",F11,0))))) | H12: =if(raw_ex!G12="^","^",if(H11="^","",if(H11="S",1,H11+if(I12="^",I11+if(G12="^",G11,0),if(G12="^",G11,0))))) -> 4 | I12: =if(raw_ex!H12="^","^",if(I11="^","",if(I11="S",1,I11+if(J12="^",J11+if(H12="^",H11,0),if(H12="^",H11,0))))) -> 3 | ... P12: =if(raw_ex!O12="^","^",if(P11="^","",if(P11="S",1,P11+if(Q12="^",Q11+if(O12="^",O11,0),if(O12="^",O11,0))))) -> 0
B13: =if(raw_ex!A13="^","^",if(B12="^","",if(B12="S",1,B12+if(C13="^",C12+if(A13="^",A12,0),if(A13="^",A12,0))))) -> 0 | C13: =if(raw_ex!B13="^","^",if(C12="^","",if(C12="S",1,C12+if(D13="^",D12+if(B13="^",B12,0),if(B13="^",B12,0))))) -> 1 | D13: =if(raw_ex!C13="^","^",if(D12="^","",if(D12="S",1,D12+if(E13="^",E12+if(C13="^",C12,0),if(C13="^",C12,0))))) -> ^ | E13: =if(raw_ex!D13="^","^",if(E12="^","",if(E12="S",1,E12+if(F13="^",F12+if(D13="^",D12,0),if(D13="^",D12,0))))) -> 1 | F13: =if(raw_ex!E13="^","^",if(F12="^","",if(F12="S",1,F12+if(G13="^",G12+if(E13="^",E12,0),if(E13="^",E12,0))))) -> 5 | G13: =if(raw_ex!F13="^","^",if(G12="^","",if(G12="S",1,G12+if(H13="^",H12+if(F13="^",F12,0),if(F13="^",F12,0))))) -> 4 | H13: =if(raw_ex!G13="^","^",if(H12="^","",if(H12="S",1,H12+if(I13="^",I12+if(G13="^",G12,0),if(G13="^",G12,0))))) -> ^ | I13: =if(raw_ex!H13="^","^",if(I12="^","",if(I12="S",1,I12+if(J13="^",J12+if(H13="^",H12,0),if(H13="^",H12,0))))) -> 7 | ... P13: =if(raw_ex!O13="^","^",if(P12="^","",if(P12="S",1,P12+if(Q13="^",Q12+if(O13="^",O12,0),if(O13="^",O12,0))))) -> 0
... B15: =if(raw_ex!A15="^","^",if(B14="^","",if(B14="S",1,B14+if(C15="^",C14+if(A15="^",A14,0),if(A15="^",A14,0))))) -> 1 | C15: =if(raw_ex!B15="^","^",if(C14="^","",if(C14="S",1,C14+if(D15="^",D14+if(B15="^",B14,0),if(B15="^",B14,0))))) -> ^ | D15: =if(raw_ex!C15="^","^",if(D14="^","",if(D14="S",1,D14+if(E15="^",E14+if(C15="^",C14,0),if(C15="^",C14,0))))) -> 2 | E15: =if(raw_ex!D15="^","^",if(E14="^","",if(E14="S",1,E14+if(F15="^",F14+if(D15="^",D14,0),if(D15="^",D14,0))))) -> ^ | F15: =if(raw_ex!E15="^","^",if(F14="^","",if(F14="S",1,F14+if(G15="^",G14+if(E15="^",E14,0),if(E15="^",E14,0))))) -> 10 | G15: =if(raw_ex!F15="^","^",if(G14="^","",if(G14="S",1,G14+if(H15="^",H14+if(F15="^",F14,0),if(F15="^",F14,0))))) -> ^ | H15: =if(raw_ex!G15="^","^",if(H14="^","",if(H14="S",1,H14+if(I15="^",I14+if(G15="^",G14,0),if(G15="^",G14,0))))) -> 11 | I15: =if(raw_ex!H15="^","^",if(I14="^","",if(I14="S",1,I14+if(J15="^",J14+if(H15="^",H14,0),if(H15="^",H14,0))))) -> ^ | ... P15: =if(raw_ex!O15="^","^",if(P14="^","",if(P14="S",1,P14+if(Q15="^",Q14+if(O15="^",O14,0),if(O15="^",O14,0))))) -> 1
B16: =if(raw_ex!A16="^","^",if(B15="^","",if(B15="S",1,B15+if(C16="^",C15+if(A16="^",A15,0),if(A16="^",A15,0))))) -> 1 | C16: =if(raw_ex!B16="^","^",if(C15="^","",if(C15="S",1,C15+if(D16="^",D15+if(B16="^",B15,0),if(B16="^",B15,0))))) | D16: =if(raw_ex!C16="^","^",if(D15="^","",if(D15="S",1,D15+if(E16="^",E15+if(C16="^",C15,0),if(C16="^",C15,0))))) -> 2 | E16: =if(raw_ex!D16="^","^",if(E15="^","",if(E15="S",1,E15+if(F16="^",F15+if(D16="^",D15,0),if(D16="^",D15,0))))) | F16: =if(raw_ex!E16="^","^",if(F15="^","",if(F15="S",1,F15+if(G16="^",G15+if(E16="^",E15,0),if(E16="^",E15,0))))) -> 10 | G16: =if(raw_ex!F16="^","^",if(G15="^","",if(G15="S",1,G15+if(H16="^",H15+if(F16="^",F15,0),if(F16="^",F15,0))))) | H16: =if(raw_ex!G16="^","^",if(H15="^","",if(H15="S",1,H15+if(I16="^",I15+if(G16="^",G15,0),if(G16="^",G15,0))))) -> 11 | I16: =if(raw_ex!H16="^","^",if(I15="^","",if(I15="S",1,I15+if(J16="^",J15+if(H16="^",H15,0),if(H16="^",H15,0))))) | ... P16: =if(raw_ex!O16="^","^",if(P15="^","",if(P15="S",1,P15+if(Q16="^",Q15+if(O16="^",O15,0),if(O16="^",O15,0))))) -> 1 | R16: =concat("Total timelines: ",sum(B16:P16)) -> Total timelines: 40
B17: =if(raw_ex!A17="^","^",if(B16="^","",if(B16="S",1,B16+if(C17="^",C16+if(A17="^",A16,0),if(A17="^",A16,0))))) -> 1 | C17: =if(raw_ex!B17="^","^",if(C16="^","",if(C16="S",1,C16+if(D17="^",D16+if(B17="^",B16,0),if(B17="^",B16,0))))) -> 0 | D17: =if(raw_ex!C17="^","^",if(D16="^","",if(D16="S",1,D16+if(E17="^",E16+if(C17="^",C16,0),if(C17="^",C16,0))))) -> 2 | E17: =if(raw_ex!D17="^","^",if(E16="^","",if(E16="S",1,E16+if(F17="^",F16+if(D17="^",D16,0),if(D17="^",D16,0))))) -> 0 | F17: =if(raw_ex!E17="^","^",if(F16="^","",if(F16="S",1,F16+if(G17="^",G16+if(E17="^",E16,0),if(E17="^",E16,0))))) -> 10 | G17: =if(raw_ex!F17="^","^",if(G16="^","",if(G16="S",1,G16+if(H17="^",H16+if(F17="^",F16,0),if(F17="^",F16,0))))) -> 0 | H17: =if(raw_ex!G17="^","^",if(H16="^","",if(H16="S",1,H16+if(I17="^",I16+if(G17="^",G16,0),if(G17="^",G16,0))))) -> 11 | I17: =if(raw_ex!H17="^","^",if(I16="^","",if(I16="S",1,I16+if(J17="^",J16+if(H17="^",H16,0),if(H17="^",H16,0))))) -> 0 | ... P17: =if(raw_ex!O17="^","^",if(P16="^","",if(P16="S",1,P16+if(Q17="^",Q16+if(O17="^",O16,0),if(O17="^",O16,0))))) -> 1
B18: =if(raw_ex!A18="^","^",if(B17="^","",if(B17="S",1,B17+if(C18="^",C17+if(A18="^",A17,0),if(A18="^",A17,0))))) -> 1 | C18: =if(raw_ex!B18="^","^",if(C17="^","",if(C17="S",1,C17+if(D18="^",D17+if(B18="^",B17,0),if(B18="^",B17,0))))) -> 0 | D18: =if(raw_ex!C18="^","^",if(D17="^","",if(D17="S",1,D17+if(E18="^",E17+if(C18="^",C17,0),if(C18="^",C17,0))))) -> 2 | E18: =if(raw_ex!D18="^","^",if(E17="^","",if(E17="S",1,E17+if(F18="^",F17+if(D18="^",D17,0),if(D18="^",D17,0))))) -> 0 | F18: =if(raw_ex!E18="^","^",if(F17="^","",if(F17="S",1,F17+if(G18="^",G17+if(E18="^",E17,0),if(E18="^",E17,0))))) -> 10 | G18: =if(raw_ex!F18="^","^",if(G17="^","",if(G17="S",1,G17+if(H18="^",H17+if(F18="^",F17,0),if(F18="^",F17,0))))) -> 0 | H18: =if(raw_ex!G18="^","^",if(H17="^","",if(H17="S",1,H17+if(I18="^",I17+if(G18="^",G17,0),if(G18="^",G17,0))))) -> 11 | I18: =if(raw_ex!H18="^","^",if(I17="^","",if(I17="S",1,I17+if(J18="^",J17+if(H18="^",H17,0),if(H18="^",H17,0))))) -> 0 | ... P18: =if(raw_ex!O18="^","^",if(P17="^","",if(P17="S",1,P17+if(Q18="^",Q17+if(O18="^",O17,0),if(O18="^",O17,0))))) -> 1
B19: =if(raw_ex!A19="^","^",if(B18="^","",if(B18="S",1,B18+if(C19="^",C18+if(A19="^",A18,0),if(A19="^",A18,0))))) -> 1 | C19: =if(raw_ex!B19="^","^",if(C18="^","",if(C18="S",1,C18+if(D19="^",D18+if(B19="^",B18,0),if(B19="^",B18,0))))) -> 0 | D19: =if(raw_ex!C19="^","^",if(D18="^","",if(D18="S",1,D18+if(E19="^",E18+if(C19="^",C18,0),if(C19="^",C18,0))))) -> 2 | E19: =if(raw_ex!D19="^","^",if(E18="^","",if(E18="S",1,E18+if(F19="^",F18+if(D19="^",D18,0),if(D19="^",D18,0))))) -> 0 | F19: =if(raw_ex!E19="^","^",if(F18="^","",if(F18="S",1,F18+if(G19="^",G18+if(E19="^",E18,0),if(E19="^",E18,0))))) -> 10 | G19: =if(raw_ex!F19="^","^",if(G18="^","",if(G18="S",1,G18+if(H19="^",H18+if(F19="^",F18,0),if(F19="^",F18,0))))) -> 0 | H19: =if(raw_ex!G19="^","^",if(H18="^","",if(H18="S",1,H18+if(I19="^",I18+if(G19="^",G18,0),if(G19="^",G18,0))))) -> 11 | I19: =if(raw_ex!H19="^","^",if(I18="^","",if(I18="S",1,I18+if(J19="^",J18+if(H19="^",H18,0),if(H19="^",H18,0))))) -> 0 | ... P19: =if(raw_ex!O19="^","^",if(P18="^","",if(P18="S",1,P18+if(Q19="^",Q18+if(O19="^",O18,0),if(O19="^",O18,0))))) -> 1
B20: =if(raw_ex!A20="^","^",if(B19="^","",if(B19="S",1,B19+if(C20="^",C19+if(A20="^",A19,0),if(A20="^",A19,0))))) -> 1 | C20: =if(raw_ex!B20="^","^",if(C19="^","",if(C19="S",1,C19+if(D20="^",D19+if(B20="^",B19,0),if(B20="^",B19,0))))) -> 0 | D20: =if(raw_ex!C20="^","^",if(D19="^","",if(D19="S",1,D19+if(E20="^",E19+if(C20="^",C19,0),if(C20="^",C19,0))))) -> 2 | E20: =if(raw_ex!D20="^","^",if(E19="^","",if(E19="S",1,E19+if(F20="^",F19+if(D20="^",D19,0),if(D20="^",D19,0))))) -> 0 | F20: =if(raw_ex!E20="^","^",if(F19="^","",if(F19="S",1,F19+if(G20="^",G19+if(E20="^",E19,0),if(E20="^",E19,0))))) -> 10 | G20: =if(raw_ex!F20="^","^",if(G19="^","",if(G19="S",1,G19+if(H20="^",H19+if(F20="^",F19,0),if(F20="^",F19,0))))) -> 0 | H20: =if(raw_ex!G20="^","^",if(H19="^","",if(H19="S",1,H19+if(I20="^",I19+if(G20="^",G19,0),if(G20="^",G19,0))))) -> 11 | I20: =if(raw_ex!H20="^","^",if(I19="^","",if(I19="S",1,I19+if(J20="^",J19+if(H20="^",H19,0),if(H20="^",H19,0))))) -> 0 | ... P20: =if(raw_ex!O20="^","^",if(P19="^","",if(P19="S",1,P19+if(Q20="^",Q19+if(O20="^",O19,0),if(O20="^",O19,0))))) -> 1
B21: =if(raw_ex!A21="^","^",if(B20="^","",if(B20="S",1,B20+if(C21="^",C20+if(A21="^",A20,0),if(A21="^",A20,0))))) -> 1 | C21: =if(raw_ex!B21="^","^",if(C20="^","",if(C20="S",1,C20+if(D21="^",D20+if(B21="^",B20,0),if(B21="^",B20,0))))) -> 0 | D21: =if(raw_ex!C21="^","^",if(D20="^","",if(D20="S",1,D20+if(E21="^",E20+if(C21="^",C20,0),if(C21="^",C20,0))))) -> 2 | E21: =if(raw_ex!D21="^","^",if(E20="^","",if(E20="S",1,E20+if(F21="^",F20+if(D21="^",D20,0),if(D21="^",D20,0))))) -> 0 | F21: =if(raw_ex!E21="^","^",if(F20="^","",if(F20="S",1,F20+if(G21="^",G20+if(E21="^",E20,0),if(E21="^",E20,0))))) -> 10 | G21: =if(raw_ex!F21="^","^",if(G20="^","",if(G20="S",1,G20+if(H21="^",H20+if(F21="^",F20,0),if(F21="^",F20,0))))) -> 0 | H21: =if(raw_ex!G21="^","^",if(H20="^","",if(H20="S",1,H20+if(I21="^",I20+if(G21="^",G20,0),if(G21="^",G20,0))))) -> 11 | I21: =if(raw_ex!H21="^","^",if(I20="^","",if(I20="S",1,I20+if(J21="^",J20+if(H21="^",H20,0),if(H21="^",H20,0))))) -> 0 | ... P21: =if(raw_ex!O21="^","^",if(P20="^","",if(P20="S",1,P20+if(Q21="^",Q20+if(O21="^",O20,0),if(O21="^",O20,0))))) -> 1
B22: =if(raw_ex!A22="^","^",if(B21="^","",if(B21="S",1,B21+if(C22="^",C21+if(A22="^",A21,0),if(A22="^",A21,0))))) -> 1 | C22: =if(raw_ex!B22="^","^",if(C21="^","",if(C21="S",1,C21+if(D22="^",D21+if(B22="^",B21,0),if(B22="^",B21,0))))) -> 0 | D22: =if(raw_ex!C22="^","^",if(D21="^","",if(D21="S",1,D21+if(E22="^",E21+if(C22="^",C21,0),if(C22="^",C21,0))))) -> 2 | E22: =if(raw_ex!D22="^","^",if(E21="^","",if(E21="S",1,E21+if(F22="^",F21+if(D22="^",D21,0),if(D22="^",D21,0))))) -> 0 | F22: =if(raw_ex!E22="^","^",if(F21="^","",if(F21="S",1,F21+if(G22="^",G21+if(E22="^",E21,0),if(E22="^",E21,0))))) -> 10 | G22: =if(raw_ex!F22="^","^",if(G21="^","",if(G21="S",1,G21+if(H22="^",H21+if(F22="^",F21,0),if(F22="^",F21,0))))) -> 0 | H22: =if(raw_ex!G22="^","^",if(H21="^","",if(H21="S",1,H21+if(I22="^",I21+if(G22="^",G21,0),if(G22="^",G21,0))))) -> 11 | I22: =if(raw_ex!H22="^","^",if(I21="^","",if(I21="S",1,I21+if(J22="^",J21+if(H22="^",H21,0),if(H22="^",H21,0))))) -> 0 | ... P22: =if(raw_ex!O22="^","^",if(P21="^","",if(P21="S",1,P21+if(Q22="^",Q21+if(O22="^",O21,0),if(O22="^",O21,0))))) -> 1
B23: =if(raw_ex!A23="^","^",if(B22="^","",if(B22="S",1,B22))) -> 1 | C23: =if(raw_ex!B23="^","^",if(C22="^","",if(C22="S",1,C22+if(D23="^",D22+if(B23="^",B22,0),if(B23="^",B22,0))))) -> 0 | D23: =if(raw_ex!C23="^","^",if(D22="^","",if(D22="S",1,D22+if(E23="^",E22+if(C23="^",C22,0),if(C23="^",C22,0))))) -> 2 | E23: =if(raw_ex!D23="^","^",if(E22="^","",if(E22="S",1,E22+if(F23="^",F22+if(D23="^",D22,0),if(D23="^",D22,0))))) -> 0 | F23: =if(raw_ex!E23="^","^",if(F22="^","",if(F22="S",1,F22+if(G23="^",G22+if(E23="^",E22,0),if(E23="^",E22,0))))) -> 10 | G23: =if(raw_ex!F23="^","^",if(G22="^","",if(G22="S",1,G22+if(H23="^",H22+if(F23="^",F22,0),if(F23="^",F22,0))))) -> 0 | H23: =if(raw_ex!G23="^","^",if(H22="^","",if(H22="S",1,H22+if(I23="^",I22+if(G23="^",G22,0),if(G23="^",G22,0))))) -> 11 | I23: =if(raw_ex!H23="^","^",if(I22="^","",if(I22="S",1,I22+if(J23="^",J22+if(H23="^",H22,0),if(H23="^",H22,0))))) -> 0 | J23: =if(raw_ex!I23="^","^",if(J22="^","",if(J22="S",1,J22+if(K23="^",K22+if(I23="^",I22,0),if(I23="^",I22,0))))) -> 11 | ... P23: =if(raw_ex!O23="^","^",if(P22="^","",if(P22="S",1,P22+if(Q23="^",Q22+if(O23="^",O22,0),if(O23="^",O22,0))))) -> 1
B24: =if(raw_ex!A24="^","^",if(B23="^","",if(B23="S",1,B23))) -> 1 | C24: =if(raw_ex!B24="^","^",if(C23="^","",if(C23="S",1,C23+if(D24="^",D23+if(B24="^",B23,0),if(B24="^",B23,0))))) -> 0 | D24: =if(raw_ex!C24="^","^",if(D23="^","",if(D23="S",1,D23+if(E24="^",E23+if(C24="^",C23,0),if(C24="^",C23,0))))) -> 2 | E24: =if(raw_ex!D24="^","^",if(E23="^","",if(E23="S",1,E23+if(F24="^",F23+if(D24="^",D23,0),if(D24="^",D23,0))))) -> 0 | F24: =if(raw_ex!E24="^","^",if(F23="^","",if(F23="S",1,F23+if(G24="^",G23+if(E24="^",E23,0),if(E24="^",E23,0))))) -> 10 | G24: =if(raw_ex!F24="^","^",if(G23="^","",if(G23="S",1,G23+if(H24="^",H23+if(F24="^",F23,0),if(F24="^",F23,0))))) -> 0 | H24: =if(raw_ex!G24="^","^",if(H23="^","",if(H23="S",1,H23+if(I24="^",I23+if(G24="^",G23,0),if(G24="^",G23,0))))) -> 11 | I24: =if(raw_ex!H24="^","^",if(I23="^","",if(I23="S",1,I23+if(J24="^",J23+if(H24="^",H23,0),if(H24="^",H23,0))))) -> 0 | J24: =if(raw_ex!I24="^","^",if(J23="^","",if(J23="S",1,J23+if(K24="^",K23+if(I24="^",I23,0),if(I24="^",I23,0))))) -> 11 | ... P24: =if(raw_ex!O24="^","^",if(P23="^","",if(P23="S",1,P23+if(Q24="^",Q23+if(O24="^",O23,0),if(O24="^",O23,0))))) -> 1
B25: =if(raw_ex!A25="^","^",if(B24="^","",if(B24="S",1,B24))) -> 1 | C25: =if(raw_ex!B25="^","^",if(C24="^","",if(C24="S",1,C24+if(D25="^",D24+if(B25="^",B24,0),if(B25="^",B24,0))))) -> 0 | D25: =if(raw_ex!C25="^","^",if(D24="^","",if(D24="S",1,D24+if(E25="^",E24+if(C25="^",C24,0),if(C25="^",C24,0))))) -> 2 | E25: =if(raw_ex!D25="^","^",if(E24="^","",if(E24="S",1,E24+if(F25="^",F24+if(D25="^",D24,0),if(D25="^",D24,0))))) -> 0 | F25: =if(raw_ex!E25="^","^",if(F24="^","",if(F24="S",1,F24+if(G25="^",G24+if(E25="^",E24,0),if(E25="^",E24,0))))) -> 10 | G25: =if(raw_ex!F25="^","^",if(G24="^","",if(G24="S",1,G24+if(H25="^",H24+if(F25="^",F24,0),if(F25="^",F24,0))))) -> 0 | H25: =if(raw_ex!G25="^","^",if(H24="^","",if(H24="S",1,H24+if(I25="^",I24+if(G25="^",G24,0),if(G25="^",G24,0))))) -> 11 | I25: =if(raw_ex!H25="^","^",if(I24="^","",if(I24="S",1,I24+if(J25="^",J24+if(H25="^",H24,0),if(H25="^",H24,0))))) -> 0 | J25: =if(raw_ex!I25="^","^",if(J24="^","",if(J24="S",1,J24+if(K25="^",K24+if(I25="^",I24,0),if(I25="^",I24,0))))) -> 11 | ... P25: =if(raw_ex!O25="^","^",if(P24="^","",if(P24="S",1,P24+if(Q25="^",Q24+if(O25="^",O24,0),if(O25="^",O24,0))))) -> 1
B26: =if(raw_ex!A26="^","^",if(B25="^","",if(B25="S",1,B25))) -> 1 | C26: =if(raw_ex!B26="^","^",if(C25="^","",if(C25="S",1,C25+if(D26="^",D25+if(B26="^",B25,0),if(B26="^",B25,0))))) -> 0 | D26: =if(raw_ex!C26="^","^",if(D25="^","",if(D25="S",1,D25+if(E26="^",E25+if(C26="^",C25,0),if(C26="^",C25,0))))) -> 2 | E26: =if(raw_ex!D26="^","^",if(E25="^","",if(E25="S",1,E25+if(F26="^",F25+if(D26="^",D25,0),if(D26="^",D25,0))))) -> 0 | F26: =if(raw_ex!E26="^","^",if(F25="^","",if(F25="S",1,F25+if(G26="^",G25+if(E26="^",E25,0),if(E26="^",E25,0))))) -> 10 | G26: =if(raw_ex!F26="^","^",if(G25="^","",if(G25="S",1,G25+if(H26="^",H25+if(F26="^",F25,0),if(F26="^",F25,0))))) -> 0 | H26: =if(raw_ex!G26="^","^",if(H25="^","",if(H25="S",1,H25+if(I26="^",I25+if(G26="^",G25,0),if(G26="^",G25,0))))) -> 11 | I26: =if(raw_ex!H26="^","^",if(I25="^","",if(I25="S",1,I25+if(J26="^",J25+if(H26="^",H25,0),if(H26="^",H25,0))))) -> 0 | J26: =if(raw_ex!I26="^","^",if(J25="^","",if(J25="S",1,J25+if(K26="^",K25+if(I26="^",I25,0),if(I26="^",I25,0))))) -> 11 | ... P26: =if(raw_ex!O26="^","^",if(P25="^","",if(P25="S",1,P25+if(Q26="^",Q25+if(O26="^",O25,0),if(O26="^",O25,0))))) -> 1
B27: =if(raw_ex!A27="^","^",if(B26="^","",if(B26="S",1,B26))) -> 1 | C27: =if(raw_ex!B27="^","^",if(C26="^","",if(C26="S",1,C26))) -> 0 | D27: =if(raw_ex!C27="^","^",if(D26="^","",if(D26="S",1,D26))) -> 2 | E27: =if(raw_ex!D27="^","^",if(E26="^","",if(E26="S",1,E26))) -> 0 | F27: =if(raw_ex!E27="^","^",if(F26="^","",if(F26="S",1,F26))) -> 10 | G27: =if(raw_ex!F27="^","^",if(G26="^","",if(G26="S",1,G26))) -> 0 | H27: =if(raw_ex!G27="^","^",if(H26="^","",if(H26="S",1,H26))) -> 11 | I27: =if(raw_ex!H27="^","^",if(I26="^","",if(I26="S",1,I26))) -> 0 | ... P27: =if(raw_ex!O27="^","^",if(P26="^","",if(P26="S",1,P26))) -> 1
B28: =if(raw_ex!A28=".","",if(raw_ex!A28="^","^",if(B27="S",1,B27))) -> 1 | C28: =if(raw_ex!B28=".","",if(raw_ex!B28="^","^",if(C27="S",1,C27))) -> 0 | D28: =if(raw_ex!C28=".","",if(raw_ex!C28="^","^",if(D27="S",1,D27))) -> 2 | E28: =if(raw_ex!D28=".","",if(raw_ex!D28="^","^",if(E27="S",1,E27))) -> 0 | F28: =if(raw_ex!E28=".","",if(raw_ex!E28="^","^",if(F27="S",1,F27))) -> 10 | G28: =if(raw_ex!F28=".","",if(raw_ex!F28="^","^",if(G27="S",1,G27))) -> 0 | H28: =if(raw_ex!G28=".","",if(raw_ex!G28="^","^",if(H27="S",1,H27))) -> 11 | I28: =if(raw_ex!H28=".","",if(raw_ex!H28="^","^",if(I27="S",1,I27))) -> 0 | ... P28: =if(raw_ex!O28=".","",if(raw_ex!O28="^","^",if(P27="S",1,P27))) -> 1
B29: =if(raw_ex!A29=".","",if(raw_ex!A29="^","^",if(B28="S",1,B28))) -> 1 | C29: =if(raw_ex!B29=".","",if(raw_ex!B29="^","^",if(C28="S",1,C28))) -> 0 | D29: =if(raw_ex!C29=".","",if(raw_ex!C29="^","^",if(D28="S",1,D28))) -> 2 | E29: =if(raw_ex!D29=".","",if(raw_ex!D29="^","^",if(E28="S",1,E28))) -> 0 | F29: =if(raw_ex!E29=".","",if(raw_ex!E29="^","^",if(F28="S",1,F28))) -> 10 | G29: =if(raw_ex!F29=".","",if(raw_ex!F29="^","^",if(G28="S",1,G28))) -> 0 | H29: =if(raw_ex!G29=".","",if(raw_ex!G29="^","^",if(H28="S",1,H28))) -> 11 | I29: =if(raw_ex!H29=".","",if(raw_ex!H29="^","^",if(I28="S",1,I28))) -> 0 | ... P29: =if(raw_ex!O29=".","",if(raw_ex!O29="^","^",if(P28="S",1,P28))) -> 1
B30: =if(raw_ex!A30=".","",if(raw_ex!A30="^","^",if(B29="S",1,B29))) -> 1 | C30: =if(raw_ex!B30=".","",if(raw_ex!B30="^","^",if(C29="S",1,C29))) -> 0 | D30: =if(raw_ex!C30=".","",if(raw_ex!C30="^","^",if(D29="S",1,D29))) -> 2 | E30: =if(raw_ex!D30=".","",if(raw_ex!D30="^","^",if(E29="S",1,E29))) -> 0 | F30: =if(raw_ex!E30=".","",if(raw_ex!E30="^","^",if(F29="S",1,F29))) -> 10 | G30: =if(raw_ex!F30=".","",if(raw_ex!F30="^","^",if(G29="S",1,G29))) -> 0 | H30: =if(raw_ex!G30=".","",if(raw_ex!G30="^","^",if(H29="S",1,H29))) -> 11 | I30: =if(raw_ex!H30=".","",if(raw_ex!H30="^","^",if(I29="S",1,I29))) -> 0 | ... P30: =if(raw_ex!O30=".","",if(raw_ex!O30="^","^",if(P29="S",1,P29))) -> 1
B31: =if(raw_ex!A31=".","",if(raw_ex!A31="^","^",if(B30="S",1,B30))) -> 1 | C31: =if(raw_ex!B31=".","",if(raw_ex!B31="^","^",if(C30="S",1,C30))) -> 0 | D31: =if(raw_ex!C31=".","",if(raw_ex!C31="^","^",if(D30="S",1,D30))) -> 2 | E31: =if(raw_ex!D31=".","",if(raw_ex!D31="^","^",if(E30="S",1,E30))) -> 0 | F31: =if(raw_ex!E31=".","",if(raw_ex!E31="^","^",if(F30="S",1,F30))) -> 10 | G31: =if(raw_ex!F31=".","",if(raw_ex!F31="^","^",if(G30="S",1,G30))) -> 0 | H31: =if(raw_ex!G31=".","",if(raw_ex!G31="^","^",if(H30="S",1,H30))) -> 11 | I31: =if(raw_ex!H31=".","",if(raw_ex!H31="^","^",if(I30="S",1,I30))) -> 0 | ... P31: =if(raw_ex!O31=".","",if(raw_ex!O31="^","^",if(P30="S",1,P30))) -> 1
B32: =if(raw_ex!A32=".","",if(raw_ex!A32="^","^",if(B31="S",1,B31))) -> 1 | C32: =if(raw_ex!B32=".","",if(raw_ex!B32="^","^",if(C31="S",1,C31))) -> 0 | D32: =if(raw_ex!C32=".","",if(raw_ex!C32="^","^",if(D31="S",1,D31))) -> 2 | E32: =if(raw_ex!D32=".","",if(raw_ex!D32="^","^",if(E31="S",1,E31))) -> 0 | F32: =if(raw_ex!E32=".","",if(raw_ex!E32="^","^",if(F31="S",1,F31))) -> 10 | G32: =if(raw_ex!F32=".","",if(raw_ex!F32="^","^",if(G31="S",1,G31))) -> 0 | H32: =if(raw_ex!G32=".","",if(raw_ex!G32="^","^",if(H31="S",1,H31))) -> 11 | I32: =if(raw_ex!H32=".","",if(raw_ex!H32="^","^",if(I31="S",1,I31))) -> 0 | ... P32: =if(raw_ex!O32=".","",if(raw_ex!O32="^","^",if(P31="S",1,P31))) -> 1
B33: =if(raw_ex!A33=".","",if(raw_ex!A33="^","^",if(B32="S",1,B32))) -> 1 | C33: =if(raw_ex!B33=".","",if(raw_ex!B33="^","^",if(C32="S",1,C32))) -> 0 | D33: =if(raw_ex!C33=".","",if(raw_ex!C33="^","^",if(D32="S",1,D32))) -> 2 | E33: =if(raw_ex!D33=".","",if(raw_ex!D33="^","^",if(E32="S",1,E32))) -> 0 | F33: =if(raw_ex!E33=".","",if(raw_ex!E33="^","^",if(F32="S",1,F32))) -> 10 | G33: =if(raw_ex!F33=".","",if(raw_ex!F33="^","^",if(G32="S",1,G32))) -> 0 | H33: =if(raw_ex!G33=".","",if(raw_ex!G33="^","^",if(H32="S",1,H32))) -> 11 | I33: =if(raw_ex!H33=".","",if(raw_ex!H33="^","^",if(I32="S",1,I32))) -> 0 | ... P33: =if(raw_ex!O33=".","",if(raw_ex!O33="^","^",if(P32="S",1,P32))) -> 1
B34: =if(raw_ex!A34=".","",if(raw_ex!A34="^","^",if(B33="S",1,B33))) -> 1 | C34: =if(raw_ex!B34=".","",if(raw_ex!B34="^","^",if(C33="S",1,C33))) -> 0 | D34: =if(raw_ex!C34=".","",if(raw_ex!C34="^","^",if(D33="S",1,D33))) -> 2 | E34: =if(raw_ex!D34=".","",if(raw_ex!D34="^","^",if(E33="S",1,E33))) -> 0 | F34: =if(raw_ex!E34=".","",if(raw_ex!E34="^","^",if(F33="S",1,F33))) -> 10 | G34: =if(raw_ex!F34=".","",if(raw_ex!F34="^","^",if(G33="S",1,G33))) -> 0 | H34: =if(raw_ex!G34=".","",if(raw_ex!G34="^","^",if(H33="S",1,H33))) -> 11 | I34: =if(raw_ex!H34=".","",if(raw_ex!H34="^","^",if(I33="S",1,I33))) -> 0 | ... P34: =if(raw_ex!O34=".","",if(raw_ex!O34="^","^",if(P33="S",1,P33))) -> 1

Sheet raw
A1: . | B1: . | C1: . | D1: . | E1: . | F1: . | G1: . | H1: . | I1: . | J1: . | K1: . | L1: . | M1: . | N1: . | O1: . | P1: . | Q1: . | R1: . | S1: . | T1: . | U1: . | V1: . | W1: . | X1: . | Y1: . | Z1: . | AA1: . | AB1: . | AC1: . | AD1: . | AE1: . | AF1: . | AG1: . | AH1: . | AI1: . | AJ1: . | AK1: . | AL1: . | AM1: . | AN1: . | AO1: . | AP1: . | AQ1: . | AR1: . | AS1: . | AT1: . | AU1: . | AV1: . | AW1: . | AX1: . | AY1: . | AZ1: . | BA1: . | BB1: . | BC1: . | BD1: . | BE1: . | BF1: . | BG1: . | BH1: . | BI1: . | BJ1: . | BK1: . | BL1: . | BM1: . | BN1: . | BO1: . | BP1: . | BQ1: . | BR1: . | BS1: S | BT1: . | BU1: . | BV1: . | BW1: . | BX1: . | BY1: . | BZ1: . | CA1: . | CB1: . | CC1: . | CD1: . | CE1: . | CF1: . | CG1: . | CH1: . | CI1: . | CJ1: . | CK1: . | CL1: . | CM1: . | CN1: . | CO1: . | CP1: . | CQ1: . | CR1: . | CS1: . | CT1: . | CU1: . | CV1: . | CW1: . | CX1: . | CY1: . | CZ1: . | DA1: . | DB1: . | DC1: . | DD1: . | DE1: . | DF1: . | DG1: . | DH1: . | DI1: . | DJ1: . | DK1: . | DL1: . | DM1: . | DN1: . | DO1: . | DP1: . | DQ1: . | DR1: . | DS1: . | DT1: . | DU1: . | DV1: . | DW1: . | DX1: . | DY1: . | DZ1: . | EA1: . | EB1: . | EC1: . | ED1: . | EE1: . | EF1: . | EG1: . | EH1: . | EI1: . | EJ1: . | EK1: .
A2: . | B2: . | C2: . | D2: . | E2: . | F2: . | G2: . | H2: . | I2: . | J2: . | K2: . | L2: . | M2: . | N2: . | O2: . | P2: . | Q2: . | R2: . | S2: . | T2: . | U2: . | V2: . | W2: . | X2: . | Y2: . | Z2: . | AA2: . | AB2: . | AC2: . | AD2: . | AE2: . | AF2: . | AG2: . | AH2: . | AI2: . | AJ2: . | AK2: . | AL2: . | AM2: . | AN2: . | AO2: . | AP2: . | AQ2: . | AR2: . | AS2: . | AT2: . | AU2: . | AV2: . | AW2: . | AX2: . | AY2: . | AZ2: . | BA2: . | BB2: . | BC2: . | BD2: . | BE2: . | BF2: . | BG2: . | BH2: . | BI2: . | BJ2: . | BK2: . | BL2: . | BM2: . | BN2: . | BO2: . | BP2: . | BQ2: . | BR2: . | BS2: . | BT2: . | BU2: . | BV2: . | BW2: . | BX2: . | BY2: . | BZ2: . | CA2: . | CB2: . | CC2: . | CD2: . | CE2: . | CF2: . | CG2: . | CH2: . | CI2: . | CJ2: . | CK2: . | CL2: . | CM2: . | CN2: . | CO2: . | CP2: . | CQ2: . | CR2: . | CS2: . | CT2: . | CU2: . | CV2: . | CW2: . | CX2: . | CY2: . | CZ2: . | DA2: . | DB2: . | DC2: . | DD2: . | DE2: . | DF2: . | DG2: . | DH2: . | DI2: . | DJ2: . | DK2: . | DL2: . | DM2: . | DN2: . | DO2: . | DP2: . | DQ2: . | DR2: . | DS2: . | DT2: . | DU2: . | DV2: . | DW2: . | DX2: . | DY2: . | DZ2: . | EA2: . | EB2: . | EC2: . | ED2: . | EE2: . | EF2: . | EG2: . | EH2: . | EI2: . | EJ2: . | EK2: .
A3: . | B3: . | C3: . | D3: . | E3: . | F3: . | G3: . | H3: . | I3: . | J3: . | K3: . | L3: . | M3: . | N3: . | O3: . | P3: . | Q3: . | R3: . | S3: . | T3: . | U3: . | V3: . | W3: . | X3: . | Y3: . | Z3: . | AA3: . | AB3: . | AC3: . | AD3: . | AE3: . | AF3: . | AG3: . | AH3: . | AI3: . | AJ3: . | AK3: . | AL3: . | AM3: . | AN3: . | AO3: . | AP3: . | AQ3: . | AR3: . | AS3: . | AT3: . | AU3: . | AV3: . | AW3: . | AX3: . | AY3: . | AZ3: . | BA3: . | BB3: . | BC3: . | BD3: . | BE3: . | BF3: . | BG3: . | BH3: . | BI3: . | BJ3: . | BK3: . | BL3: . | BM3: . | BN3: . | BO3: . | BP3: . | BQ3: . | BR3: . | BS3: ^ | BT3: . | BU3: . | BV3: . | BW3: . | BX3: . | BY3: . | BZ3: . | CA3: . | CB3: . | CC3: . | CD3: . | CE3: . | CF3: . | CG3: . | CH3: . | CI3: . | CJ3: . | CK3: . | CL3: . | CM3: . | CN3: . | CO3: . | CP3: . | CQ3: . | CR3: . | CS3: . | CT3: . | CU3: . | CV3: . | CW3: . | CX3: . | CY3: . | CZ3: . | DA3: . | DB3: . | DC3: . | DD3: . | DE3: . | DF3: . | DG3: . | DH3: . | DI3: . | DJ3: . | DK3: . | DL3: . | DM3: . | DN3: . | DO3: . | DP3: . | DQ3: . | DR3: . | DS3: . | DT3: . | DU3: . | DV3: . | DW3: . | DX3: . | DY3: . | DZ3: . | EA3: . | EB3: . | EC3: . | ED3: . | EE3: . | EF3: . | EG3: . | EH3: . | EI3: . | EJ3: . | EK3: .
A4: . | B4: . | C4: . | D4: . | E4: . | F4: . | G4: . | H4: . | I4: . | J4: . | K4: . | L4: . | M4: . | N4: . | O4: . | P4: . | Q4: . | R4: . | S4: . | T4: . | U4: . | V4: . | W4: . | X4: . | Y4: . | Z4: . | AA4: . | AB4: . | AC4: . | AD4: . | AE4: . | AF4: . | AG4: . | AH4: . | AI4: . | AJ4: . | AK4: . | AL4: . | AM4: . | AN4: . | AO4: . | AP4: . | AQ4: . | AR4: . | AS4: . | AT4: . | AU4: . | AV4: . | AW4: . | AX4: . | AY4: . | AZ4: . | BA4: . | BB4: . | BC4: . | BD4: . | BE4: . | BF4: . | BG4: . | BH4: . | BI4: . | BJ4: . | BK4: . | BL4: . | BM4: . | BN4: . | BO4: . | BP4: . | BQ4: . | BR4: . | BS4: . | BT4: . | BU4: . | BV4: . | BW4: . | BX4: . | BY4: . | BZ4: . | CA4: . | CB4: . | CC4: . | CD4: . | CE4: . | CF4: . | CG4: . | CH4: . | CI4: . | CJ4: . | CK4: . | CL4: . | CM4: . | CN4: . | CO4: . | CP4: . | CQ4: . | CR4: . | CS4: . | CT4: . | CU4: . | CV4: . | CW4: . | CX4: . | CY4: . | CZ4: . | DA4: . | DB4: . | DC4: . | DD4: . | DE4: . | DF4: . | DG4: . | DH4: . | DI4: . | DJ4: . | DK4: . | DL4: . | DM4: . | DN4: . | DO4: . | DP4: . | DQ4: . | DR4: . | DS4: . | DT4: . | DU4: . | DV4: . | DW4: . | DX4: . | DY4: . | DZ4: . | EA4: . | EB4: . | EC4: . | ED4: . | EE4: . | EF4: . | EG4: . | EH4: . | EI4: . | EJ4: . | EK4: .
A5: . | B5: . | C5: . | D5: . | E5: . | F5: . | G5: . | H5: . | I5: . | J5: . | K5: . | L5: . | M5: . | N5: . | O5: . | P5: . | Q5: . | R5: . | S5: . | T5: . | U5: . | V5: . | W5: . | X5: . | Y5: . | Z5: . | AA5: . | AB5: . | AC5: . | AD5: . | AE5: . | AF5: . | AG5: . | AH5: . | AI5: . | AJ5: . | AK5: . | AL5: . | AM5: . | AN5: . | AO5: . | AP5: . | AQ5: . | AR5: . | AS5: . | AT5: . | AU5: . | AV5: . | AW5: . | AX5: . | AY5: . | AZ5: . | BA5: . | BB5: . | BC5: . | BD5: . | BE5: . | BF5: . | BG5: . | BH5: . | BI5: . | BJ5: . | BK5: . | BL5: . | BM5: . | BN5: . | BO5: . | BP5: . | BQ5: . | BR5: ^ | BS5: . | BT5: ^ | BU5: . | BV5: . | BW5: . | BX5: . | BY5: . | BZ5: . | CA5: . | CB5: . | CC5: . | CD5: . | CE5: . | CF5: . | CG5: . | CH5: . | CI5: . | CJ5: . | CK5: . | CL5: . | CM5: . | CN5: . | CO5: . | CP5: . | CQ5: . | CR5: . | CS5: . | CT5: . | CU5: . | CV5: . | CW5: . | CX5: . | CY5: . | CZ5: . | DA5: . | DB5: . | DC5: . | DD5: . | DE5: . | DF5: . | DG5: . | DH5: . | DI5: . | DJ5: . | DK5: . | DL5: . | DM5: . | DN5: . | DO5: . | DP5: . | DQ5: . | DR5: . | DS5: . | DT5: . | DU5: . | DV5: . | DW5: . | DX5: . | DY5: . | DZ5: . | EA5: . | EB5: . | EC5: . | ED5: . | EE5: . | EF5: . | EG5: . | EH5: . | EI5: . | EJ5: . | EK5: .
A6: . | B6: . | C6: . | D6: . | E6: . | F6: . | G6: . | H6: . | I6: . | J6: . | K6: . | L6: . | M6: . | N6: . | O6: . | P6: . | Q6: . | R6: . | S6: . | T6: . | U6: . | V6: . | W6: . | X6: . | Y6: . | Z6: . | AA6: . | AB6: . | AC6: . | AD6: . | AE6: . | AF6: . | AG6: . | AH6: . | AI6: . | AJ6: . | AK6: . | AL6: . | AM6: . | AN6: . | AO6: . | AP6: . | AQ6: . | AR6: . | AS6: . | AT6: . | AU6: . | AV6: . | AW6: . | AX6: . | AY6: . | AZ6: . | BA6: . | BB6: . | BC6: . | BD6: . | BE6: . | BF6: . | BG6: . | BH6: . | BI6: . | BJ6: . | BK6: . | BL6: . | BM6: . | BN6: . | BO6: . | BP6: . | BQ6: . | BR6: . | BS6: . | BT6: . | BU6: . | BV6: . | BW6: . | BX6: . | BY6: . | BZ6: . | CA6: . | CB6: . | CC6: . | CD6: . | CE6: . | CF6: . | CG6: . | CH6: . | CI6: . | CJ6: . | CK6: . | CL6: . | CM6: . | CN6: . | CO6: . | CP6: . | CQ6: . | CR6: . | CS6: . | CT6: . | CU6: . | CV6: . | CW6: . | CX6: . | CY6: . | CZ6: . | DA6: . | DB6: . | DC6: . | DD6: . | DE6: . | DF6: . | DG6: . | DH6: . | DI6: . | DJ6: . | DK6: . | DL6: . | DM6: . | DN6: . | DO6: . | DP6: . | DQ6: . | DR6: . | DS6: . | DT6: . | DU6: . | DV6: . | DW6: . | DX6: . | DY6: . | DZ6: . | EA6: . | EB6: . | EC6: . | ED6: . | EE6: . | EF6: . | EG6: . | EH6: . | EI6: . | EJ6: . | EK6: .
A7: . | B7: . | C7: . | D7: . | E7: . | F7: . | G7: . | H7: . | I7: . | J7: . | K7: . | L7: . | M7: . | N7: . | O7: . | P7: . | Q7: . | R7: . | S7: . | T7: . | U7: . | V7: . | W7: . | X7: . | Y7: . | Z7: . | AA7: . | AB7: . | AC7: . | AD7: . | AE7: . | AF7: . | AG7: . | AH7: . | AI7: . | AJ7: . | AK7: . | AL7: . | AM7: . | AN7: . | AO7: . | AP7: . | AQ7: . | AR7: . | AS7: . | AT7: . | AU7: . | AV7: . | AW7: . | AX7: . | AY7: . | AZ7: . | BA7: . | BB7: . | BC7: . | BD7: . | BE7: . | BF7: . | BG7: . | BH7: . | BI7: . | BJ7: . | BK7: . | BL7: . | BM7: . | BN7: . | BO7: . | BP7: . | BQ7: ^ | BR7: . | BS7: ^ | BT7: . | BU7: ^ | BV7: . | BW7: . | BX7: . | BY7: . | BZ7: . | CA7: . | CB7: . | CC7: . | CD7: . | CE7: . | CF7: . | CG7: . | CH7: . | CI7: . | CJ7: . | CK7: . | CL7: . | CM7: . | CN7: . | CO7: . | CP7: . | CQ7: . | CR7: . | CS7: . | CT7: . | CU7: . | CV7: . | CW7: . | CX7: . | CY7: . | CZ7: . | DA7: . | DB7: . | DC7: . | DD7: . | DE7: . | DF7: . | DG7: . | DH7: . | DI7: . | DJ7: . | DK7: . | DL7: . | DM7: . | DN7: . | DO7: . | DP7: . | DQ7: . | DR7: . | DS7: . | DT7: . | DU7: . | DV7: . | DW7: . | DX7: . | DY7: . | DZ7: . | EA7: . | EB7: . | EC7: . | ED7: . | EE7: . | EF7: . | EG7: . | EH7: . | EI7: . | EJ7: . | EK7: .
A8: . | B8: . | C8: . | D8: . | E8: . | F8: . | G8: . | H8: . | I8: . | J8: . | K8: . | L8: . | M8: . | N8: . | O8: . | P8: . | Q8: . | R8: . | S8: . | T8: . | U8: . | V8: . | W8: . | X8: . | Y8: . | Z8: . | AA8: . | AB8: . | AC8: . | AD8: . | AE8: . | AF8: . | AG8: . | AH8: . | AI8: . | AJ8: . | AK8: . | AL8: . | AM8: . | AN8: . | AO8: . | AP8: . | AQ8: . | AR8: . | AS8: . | AT8: . | AU8: . | AV8: . | AW8: . | AX8: . | AY8: . | AZ8: . | BA8: . | BB8: . | BC8: . | BD8: . | BE8: . | BF8: . | BG8: . | BH8: . | BI8: . | BJ8: . | BK8: . | BL8: . | BM8: . | BN8: . | BO8: . | BP8: . | BQ8: . | BR8: . | BS8: . | BT8: . | BU8: . | BV8: . | BW8: . | BX8: . | BY8: . | BZ8: . | CA8: . | CB8: . | CC8: . | CD8: . | CE8: . | CF8: . | CG8: . | CH8: . | CI8: . | CJ8: . | CK8: . | CL8: . | CM8: . | CN8: . | CO8: . | CP8: . | CQ8: . | CR8: . | CS8: . | CT8: . | CU8: . | CV8: . | CW8: . | CX8: . | CY8: . | CZ8: . | DA8: . | DB8: . | DC8: . | DD8: . | DE8: . | DF8: . | DG8: . | DH8: . | DI8: . | DJ8: . | DK8: . | DL8: . | DM8: . | DN8: . | DO8: . | DP8: . | DQ8: . | DR8: . | DS8: . | DT8: . | DU8: . | DV8: . | DW8: . | DX8: . | DY8: . | DZ8: . | EA8: . | EB8: . | EC8: . | ED8: . | EE8: . | EF8: . | EG8: . | EH8: . | EI8: . | EJ8: . | EK8: .
A9: . | B9: . | C9: . | D9: . | E9: . | F9: . | G9: . | H9: . | I9: . | J9: . | K9: . | L9: . | M9: . | N9: . | O9: . | P9: . | Q9: . | R9: . | S9: . | T9: . | U9: . | V9: . | W9: . | X9: . | Y9: . | Z9: . | AA9: . | AB9: . | AC9: . | AD9: . | AE9: . | AF9: . | AG9: . | AH9: . | AI9: . | AJ9: . | AK9: . | AL9: . | AM9: . | AN9: . | AO9: . | AP9: . | AQ9: . | AR9: . | AS9: . | AT9: . | AU9: . | AV9: . | AW9: . | AX9: . | AY9: . | AZ9: . | BA9: . | BB9: . | BC9: . | BD9: . | BE9: . | BF9: . | BG9: . | BH9: . | BI9: . | BJ9: . | BK9: . | BL9: . | BM9: . | BN9: . | BO9: . | BP9: ^ | BQ9: . | BR9: ^ | BS9: . | BT9: . | BU9: . | BV9: ^ | BW9: . | BX9: . | BY9: . | BZ9: . | CA9: . | CB9: . | CC9: . | CD9: . | CE9: . | CF9: . | CG9: . | CH9: . | CI9: . | CJ9: . | CK9: . | CL9: . | CM9: . | CN9: . | CO9: . | CP9: . | CQ9: . | CR9: . | CS9: . | CT9: . | CU9: . | CV9: . | CW9: . | CX9: . | CY9: . | CZ9: . | DA9: . | DB9: . | DC9: . | DD9: . | DE9: . | DF9: . | DG9: . | DH9: . | DI9: . | DJ9: . | DK9: . | DL9: . | DM9: . | DN9: . | DO9: . | DP9: . | DQ9: . | DR9: . | DS9: . | DT9: . | DU9: . | DV9: . | DW9: . | DX9: . | DY9: . | DZ9: . | EA9: . | EB9: . | EC9: . | ED9: . | EE9: . | EF9: . | EG9: . | EH9: . | EI9: . | EJ9: . | EK9: .
A10: . | B10: . | C10: . | D10: . | E10: . | F10: . | G10: . | H10: . | I10: . | J10: . | K10: . | L10: . | M10: . | N10: . | O10: . | P10: . | Q10: . | R10: . | S10: . | T10: . | U10: . | V10: . | W10: . | X10: . | Y10: . | Z10: . | AA10: . | AB10: . | AC10: . | AD10: . | AE10: . | AF10: . | AG10: . | AH10: . | AI10: . | AJ10: . | AK10: . | AL10: . | AM10: . | AN10: . | AO10: . | AP10: . | AQ10: . | AR10: . | AS10: . | AT10: . | AU10: . | AV10: . | AW10: . | AX10: . | AY10: . | AZ10: . | BA10: . | BB10: . | BC10: . | BD10: . | BE10: . | BF10: . | BG10: . | BH10: . | BI10: . | BJ10: . | BK10: . | BL10: . | BM10: . | BN10: . | BO10: . | BP10: . | BQ10: . | BR10: . | BS10: . | BT10: . | BU10: . | BV10: . | BW10: . | BX10: . | BY10: . | BZ10: . | CA10: . | CB10: . | CC10: . | CD10: . | CE10: . | CF10: . | CG10: . | CH10: . | CI10: . | CJ10: . | CK10: . | CL10: . | CM10: . | CN10: . | CO10: . | CP10: . | CQ10: . | CR10: . | CS10: . | CT10: . | CU10: . | CV10: . | CW10: . | CX10: . | CY10: . | CZ10: . | DA10: . | DB10: . | DC10: . | DD10: . | DE10: . | DF10: . | DG10: . | DH10: . | DI10: . | DJ10: . | DK10: . | DL10: . | DM10: . | DN10: . | DO10: . | DP10: . | DQ10: . | DR10: . | DS10: . | DT10: . | DU10: . | DV10: . | DW10: . | DX10: . | DY10: . | DZ10: . | EA10: . | EB10: . | EC10: . | ED10: . | EE10: . | EF10: . | EG10: . | EH10: . | EI10: . | EJ10: . | EK10: .
A11: . | B11: . | C11: . | D11: . | E11: . | F11: . | G11: . | H11: . | I11: . | J11: . | K11: . | L11: . | M11: . | N11: . | O11: . | P11: . | Q11: . | R11: . | S11: . | T11: . | U11: . | V11: . | W11: . | X11: . | Y11: . | Z11: . | AA11: . | AB11: . | AC11: . | AD11: . | AE11: . | AF11: . | AG11: . | AH11: . | AI11: . | AJ11: . | AK11: . | AL11: . | AM11: . | AN11: . | AO11: . | AP11: . | AQ11: . | AR11: . | AS11: . | AT11: . | AU11: . | AV11: . | AW11: . | AX11: . | AY11: . | AZ11: . | BA11: . | BB11: . | BC11: . | BD11: . | BE11: . | BF11: . | BG11: . | BH11: . | BI11: . | BJ11: . | BK11: . | BL11: . | BM11: . | BN11: . | BO11: ^ | BP11: . | BQ11: ^ | BR11: . | BS11: . | BT11: . | BU11: ^ | BV11: . | BW11: ^ | BX11: . | BY11: . | BZ11: . | CA11: . | CB11: . | CC11: . | CD11: . | CE11: . | CF11: . | CG11: . | CH11: . | CI11: . | CJ11: . | CK11: . | CL11: . | CM11: . | CN11: . | CO11: . | CP11: . | CQ11: . | CR11: . | CS11: . | CT11: . | CU11: . | CV11: . | CW11: . | CX11: . | CY11: . | CZ11: . | DA11: . | DB11: . | DC11: . | DD11: . | DE11: . | DF11: . | DG11: . | DH11: . | DI11: . | DJ11: . | DK11: . | DL11: . | DM11: . | DN11: . | DO11: . | DP11: . | DQ11: . | DR11: . | DS11: . | DT11: . | DU11: . | DV11: . | DW11: . | DX11: . | DY11: . | DZ11: . | EA11: . | EB11: . | EC11: . | ED11: . | EE11: . | EF11: . | EG11: . | EH11: . | EI11: . | EJ11: . | EK11: .
A12: . | B12: . | C12: . | D12: . | E12: . | F12: . | G12: . | H12: . | I12: . | J12: . | K12: . | L12: . | M12: . | N12: . | O12: . | P12: . | Q12: . | R12: . | S12: . | T12: . | U12: . | V12: . | W12: . | X12: . | Y12: . | Z12: . | AA12: . | AB12: . | AC12: . | AD12: . | AE12: . | AF12: . | AG12: . | AH12: . | AI12: . | AJ12: . | AK12: . | AL12: . | AM12: . | AN12: . | AO12: . | AP12: . | AQ12: . | AR12: . | AS12: . | AT12: . | AU12: . | AV12: . | AW12: . | AX12: . | AY12: . | AZ12: . | BA12: . | BB12: . | BC12: . | BD12: . | BE12: . | BF12: . | BG12: . | BH12: . | BI12: . | BJ12: . | BK12: . | BL12: . | BM12: . | BN12: . | BO12: . | BP12: . | BQ12: . | BR12: . | BS12: . | BT12: . | BU12: . | BV12: . | BW12: . | BX12: . | BY12: . | BZ12: . | CA12: . | CB12: . | CC12: . | CD12: . | CE12: . | CF12: . | CG12: . | CH12: . | CI12: . | CJ12: . | CK12: . | CL12: . | CM12: . | CN12: . | CO12: . | CP12: . | CQ12: . | CR12: . | CS12: . | CT12: . | CU12: . | CV12: . | CW12: . | CX12: . | CY12: . | CZ12: . | DA12: . | DB12: . | DC12: . | DD12: . | DE12: . | DF12: . | DG12: . | DH12: . | DI12: . | DJ12: . | DK12: . | DL12: . | DM12: . | DN12: . | DO12: . | DP12: . | DQ12: . | DR12: . | DS12: . | DT12: . | DU12: . | DV12: . | DW12: . | DX12: . | DY12: . | DZ12: . | EA12: . | EB12: . | EC12: . | ED12: . | EE12: . | EF12: . | EG12: . | EH12: . | EI12: . | EJ12: . | EK12: .
... A142: . | B142: . | C142: . | D142: . | E142: . | F142: . | G142: . | H142: . | I142: . | J142: . | K142: . | L142: . | M142: . | N142: . | O142: . | P142: . | Q142: . | R142: . | S142: . | T142: . | U142: . | V142: . | W142: . | X142: . | Y142: . | Z142: . | AA142: . | AB142: . | AC142: . | AD142: . | AE142: . | AF142: . | AG142: . | AH142: . | AI142: . | AJ142: . | AK142: . | AL142: . | AM142: . | AN142: . | AO142: . | AP142: . | AQ142: . | AR142: . | AS142: . | AT142: . | AU142: . | AV142: . | AW142: . | AX142: . | AY142: . | AZ142: . | BA142: . | BB142: . | BC142: . | BD142: . | BE142: . | BF142: . | BG142: . | BH142: . | BI142: . | BJ142: . | BK142: . | BL142: . | BM142: . | BN142: . | BO142: . | BP142: . | BQ142: . | BR142: . | BS142: . | BT142: . | BU142: . | BV142: . | BW142: . | BX142: . | BY142: . | BZ142: . | CA142: . | CB142: . | CC142: . | CD142: . | CE142: . | CF142: . | CG142: . | CH142: . | CI142: . | CJ142: . | CK142: . | CL142: . | CM142: . | CN142: . | CO142: . | CP142: . | CQ142: . | CR142: . | CS142: . | CT142: . | CU142: . | CV142: . | CW142: . | CX142: . | CY142: . | CZ142: . | DA142: . | DB142: . | DC142: . | DD142: . | DE142: . | DF142: . | DG142: . | DH142: . | DI142: . | DJ142: . | DK142: . | DL142: . | DM142: . | DN142: . | DO142: . | DP142: . | DQ142: . | DR142: . | DS142: . | DT142: . | DU142: . | DV142: . | DW142: . | DX142: . | DY142: . | DZ142: . | EA142: . | EB142: . | EC142: . | ED142: . | EE142: . | EF142: . | EG142: . | EH142: . | EI142: . | EJ142: . | EK142: .

Sheet Copy of Example solution
B1: =if(raw!A1=".","",raw!A1) | C1: =if(raw!B1=".","",raw!B1) | D1: =if(raw!C1=".","",raw!C1) | E1: =if(raw!D1=".","",raw!D1) | F1: =if(raw!E1=".","",raw!E1) | G1: =if(raw!F1=".","",raw!F1) | H1: =if(raw!G1=".","",raw!G1) | I1: =if(raw!H1=".","",raw!H1) | ... EL1: =if(raw!EK1=".","",raw!EK1)
B2: =if(raw!A2="^","^",if(B1="^","",if(B1="S",1,B1+if(C2="^",C1+if(A2="^",A1,0),if(A2="^",A1,0))))) -> 0 | C2: =if(raw!B2="^","^",if(C1="^","",if(C1="S",1,C1+if(D2="^",D1+if(B2="^",B1,0),if(B2="^",B1,0))))) -> 0 | D2: =if(raw!C2="^","^",if(D1="^","",if(D1="S",1,D1+if(E2="^",E1+if(C2="^",C1,0),if(C2="^",C1,0))))) -> 0 | E2: =if(raw!D2="^","^",if(E1="^","",if(E1="S",1,E1+if(F2="^",F1+if(D2="^",D1,0),if(D2="^",D1,0))))) -> 0 | F2: =if(raw!E2="^","^",if(F1="^","",if(F1="S",1,F1+if(G2="^",G1+if(E2="^",E1,0),if(E2="^",E1,0))))) -> 0 | G2: =if(raw!F2="^","^",if(G1="^","",if(G1="S",1,G1+if(H2="^",H1+if(F2="^",F1,0),if(F2="^",F1,0))))) -> 0 | H2: =if(raw!G2="^","^",if(H1="^","",if(H1="S",1,H1+if(I2="^",I1+if(G2="^",G1,0),if(G2="^",G1,0))))) -> 0 | I2: =if(raw!H2="^","^",if(I1="^","",if(I1="S",1,I1+if(J2="^",J1+if(H2="^",H1,0),if(H2="^",H1,0))))) -> 0 | ... EL2: =if(raw!EK2="^","^",if(EL1="^","",if(EL1="S",1,EL1+if(EM2="^",EM1+if(EK2="^",EK1,0),if(EK2="^",EK1,0))))) -> 0
B3: =if(raw!A3="^","^",if(B2="^","",if(B2="S",1,B2+if(C3="^",C2+if(A3="^",A2,0),if(A3="^",A2,0))))) -> 0 | C3: =if(raw!B3="^","^",if(C2="^","",if(C2="S",1,C2+if(D3="^",D2+if(B3="^",B2,0),if(B3="^",B2,0))))) -> 0 | D3: =if(raw!C3="^","^",if(D2="^","",if(D2="S",1,D2+if(E3="^",E2+if(C3="^",C2,0),if(C3="^",C2,0))))) -> 0 | E3: =if(raw!D3="^","^",if(E2="^","",if(E2="S",1,E2+if(F3="^",F2+if(D3="^",D2,0),if(D3="^",D2,0))))) -> 0 | F3: =if(raw!E3="^","^",if(F2="^","",if(F2="S",1,F2+if(G3="^",G2+if(E3="^",E2,0),if(E3="^",E2,0))))) -> 0 | G3: =if(raw!F3="^","^",if(G2="^","",if(G2="S",1,G2+if(H3="^",H2+if(F3="^",F2,0),if(F3="^",F2,0))))) -> 0 | H3: =if(raw!G3="^","^",if(H2="^","",if(H2="S",1,H2+if(I3="^",I2+if(G3="^",G2,0),if(G3="^",G2,0))))) -> 0 | I3: =if(raw!H3="^","^",if(I2="^","",if(I2="S",1,I2+if(J3="^",J2+if(H3="^",H2,0),if(H3="^",H2,0))))) -> 0 | ... EL3: =if(raw!EK3="^","^",if(EL2="^","",if(EL2="S",1,EL2+if(EM3="^",EM2+if(EK3="^",EK2,0),if(EK3="^",EK2,0))))) -> 0
B4: =if(raw!A4="^","^",if(B3="^","",if(B3="S",1,B3+if(C4="^",C3+if(A4="^",A3,0),if(A4="^",A3,0))))) -> 0 | C4: =if(raw!B4="^","^",if(C3="^","",if(C3="S",1,C3+if(D4="^",D3+if(B4="^",B3,0),if(B4="^",B3,0))))) -> 0 | D4: =if(raw!C4="^","^",if(D3="^","",if(D3="S",1,D3+if(E4="^",E3+if(C4="^",C3,0),if(C4="^",C3,0))))) -> 0 | E4: =if(raw!D4="^","^",if(E3="^","",if(E3="S",1,E3+if(F4="^",F3+if(D4="^",D3,0),if(D4="^",D3,0))))) -> 0 | F4: =if(raw!E4="^","^",if(F3="^","",if(F3="S",1,F3+if(G4="^",G3+if(E4="^",E3,0),if(E4="^",E3,0))))) -> 0 | G4: =if(raw!F4="^","^",if(G3="^","",if(G3="S",1,G3+if(H4="^",H3+if(F4="^",F3,0),if(F4="^",F3,0))))) -> 0 | H4: =if(raw!G4="^","^",if(H3="^","",if(H3="S",1,H3+if(I4="^",I3+if(G4="^",G3,0),if(G4="^",G3,0))))) -> 0 | I4: =if(raw!H4="^","^",if(I3="^","",if(I3="S",1,I3+if(J4="^",J3+if(H4="^",H3,0),if(H4="^",H3,0))))) -> 0 | ... EL4: =if(raw!EK4="^","^",if(EL3="^","",if(EL3="S",1,EL3+if(EM4="^",EM3+if(EK4="^",EK3,0),if(EK4="^",EK3,0))))) -> 0
B5: =if(raw!A5="^","^",if(B4="^","",if(B4="S",1,B4+if(C5="^",C4+if(A5="^",A4,0),if(A5="^",A4,0))))) -> 0 | C5: =if(raw!B5="^","^",if(C4="^","",if(C4="S",1,C4+if(D5="^",D4+if(B5="^",B4,0),if(B5="^",B4,0))))) -> 0 | D5: =if(raw!C5="^","^",if(D4="^","",if(D4="S",1,D4+if(E5="^",E4+if(C5="^",C4,0),if(C5="^",C4,0))))) -> 0 | E5: =if(raw!D5="^","^",if(E4="^","",if(E4="S",1,E4+if(F5="^",F4+if(D5="^",D4,0),if(D5="^",D4,0))))) -> 0 | F5: =if(raw!E5="^","^",if(F4="^","",if(F4="S",1,F4+if(G5="^",G4+if(E5="^",E4,0),if(E5="^",E4,0))))) -> 0 | G5: =if(raw!F5="^","^",if(G4="^","",if(G4="S",1,G4+if(H5="^",H4+if(F5="^",F4,0),if(F5="^",F4,0))))) -> 0 | H5: =if(raw!G5="^","^",if(H4="^","",if(H4="S",1,H4+if(I5="^",I4+if(G5="^",G4,0),if(G5="^",G4,0))))) -> 0 | I5: =if(raw!H5="^","^",if(I4="^","",if(I4="S",1,I4+if(J5="^",J4+if(H5="^",H4,0),if(H5="^",H4,0))))) -> 0 | ... EL5: =if(raw!EK5="^","^",if(EL4="^","",if(EL4="S",1,EL4+if(EM5="^",EM4+if(EK5="^",EK4,0),if(EK5="^",EK4,0))))) -> 0
B6: =if(raw!A6="^","^",if(B5="^","",if(B5="S",1,B5+if(C6="^",C5+if(A6="^",A5,0),if(A6="^",A5,0))))) -> 0 | C6: =if(raw!B6="^","^",if(C5="^","",if(C5="S",1,C5+if(D6="^",D5+if(B6="^",B5,0),if(B6="^",B5,0))))) -> 0 | D6: =if(raw!C6="^","^",if(D5="^","",if(D5="S",1,D5+if(E6="^",E5+if(C6="^",C5,0),if(C6="^",C5,0))))) -> 0 | E6: =if(raw!D6="^","^",if(E5="^","",if(E5="S",1,E5+if(F6="^",F5+if(D6="^",D5,0),if(D6="^",D5,0))))) -> 0 | F6: =if(raw!E6="^","^",if(F5="^","",if(F5="S",1,F5+if(G6="^",G5+if(E6="^",E5,0),if(E6="^",E5,0))))) -> 0 | G6: =if(raw!F6="^","^",if(G5="^","",if(G5="S",1,G5+if(H6="^",H5+if(F6="^",F5,0),if(F6="^",F5,0))))) -> 0 | H6: =if(raw!G6="^","^",if(H5="^","",if(H5="S",1,H5+if(I6="^",I5+if(G6="^",G5,0),if(G6="^",G5,0))))) -> 0 | I6: =if(raw!H6="^","^",if(I5="^","",if(I5="S",1,I5+if(J6="^",J5+if(H6="^",H5,0),if(H6="^",H5,0))))) -> 0 | ... EL6: =if(raw!EK6="^","^",if(EL5="^","",if(EL5="S",1,EL5+if(EM6="^",EM5+if(EK6="^",EK5,0),if(EK6="^",EK5,0))))) -> 0
B7: =if(raw!A7="^","^",if(B6="^","",if(B6="S",1,B6+if(C7="^",C6+if(A7="^",A6,0),if(A7="^",A6,0))))) -> 0 | C7: =if(raw!B7="^","^",if(C6="^","",if(C6="S",1,C6+if(D7="^",D6+if(B7="^",B6,0),if(B7="^",B6,0))))) -> 0 | D7: =if(raw!C7="^","^",if(D6="^","",if(D6="S",1,D6+if(E7="^",E6+if(C7="^",C6,0),if(C7="^",C6,0))))) -> 0 | E7: =if(raw!D7="^","^",if(E6="^","",if(E6="S",1,E6+if(F7="^",F6+if(D7="^",D6,0),if(D7="^",D6,0))))) -> 0 | F7: =if(raw!E7="^","^",if(F6="^","",if(F6="S",1,F6+if(G7="^",G6+if(E7="^",E6,0),if(E7="^",E6,0))))) -> 0 | G7: =if(raw!F7="^","^",if(G6="^","",if(G6="S",1,G6+if(H7="^",H6+if(F7="^",F6,0),if(F7="^",F6,0))))) -> 0 | H7: =if(raw!G7="^","^",if(H6="^","",if(H6="S",1,H6+if(I7="^",I6+if(G7="^",G6,0),if(G7="^",G6,0))))) -> 0 | I7: =if(raw!H7="^","^",if(I6="^","",if(I6="S",1,I6+if(J7="^",J6+if(H7="^",H6,0),if(H7="^",H6,0))))) -> 0 | ... EL7: =if(raw!EK7="^","^",if(EL6="^","",if(EL6="S",1,EL6+if(EM7="^",EM6+if(EK7="^",EK6,0),if(EK7="^",EK6,0))))) -> 0
B8: =if(raw!A8="^","^",if(B7="^","",if(B7="S",1,B7+if(C8="^",C7+if(A8="^",A7,0),if(A8="^",A7,0))))) -> 0 | C8: =if(raw!B8="^","^",if(C7="^","",if(C7="S",1,C7+if(D8="^",D7+if(B8="^",B7,0),if(B8="^",B7,0))))) -> 0 | D8: =if(raw!C8="^","^",if(D7="^","",if(D7="S",1,D7+if(E8="^",E7+if(C8="^",C7,0),if(C8="^",C7,0))))) -> 0 | E8: =if(raw!D8="^","^",if(E7="^","",if(E7="S",1,E7+if(F8="^",F7+if(D8="^",D7,0),if(D8="^",D7,0))))) -> 0 | F8: =if(raw!E8="^","^",if(F7="^","",if(F7="S",1,F7+if(G8="^",G7+if(E8="^",E7,0),if(E8="^",E7,0))))) -> 0 | G8: =if(raw!F8="^","^",if(G7="^","",if(G7="S",1,G7+if(H8="^",H7+if(F8="^",F7,0),if(F8="^",F7,0))))) -> 0 | H8: =if(raw!G8="^","^",if(H7="^","",if(H7="S",1,H7+if(I8="^",I7+if(G8="^",G7,0),if(G8="^",G7,0))))) -> 0 | I8: =if(raw!H8="^","^",if(I7="^","",if(I7="S",1,I7+if(J8="^",J7+if(H8="^",H7,0),if(H8="^",H7,0))))) -> 0 | ... EL8: =if(raw!EK8="^","^",if(EL7="^","",if(EL7="S",1,EL7+if(EM8="^",EM7+if(EK8="^",EK7,0),if(EK8="^",EK7,0))))) -> 0
